Workbook
Name Slicer_Коэффициент: #N/A
Name Slicer_Месяц_отчета: #N/A

Sheet Dashboard
A1: Ключевые KPI отдела
A2: Коэффициент M1, год | B2: Коэффициент M2, год | C2: Проектов M1 | D2: Проектов M2 | E2: Продлено проектов всего | F2: Вернувшаяся выручка, ₽
A3: =G44 -> 0.54221628 | B3: =M44 -> 0.075587156 | C3: =B44 -> 380 | D3: =H44 -> 209 | E3: =C44+I44 -> 177 | F3: =N44 -> 19316172
A6: Динамика отдела по месяцам
A7: Месяц | B7: M1 | C7: M2 | D7: M1 база, ₽ | E7: M2 база, ₽
A8: Январь 2023 | B8: =IFERROR(SUMIFS('M1'!$F:$F,'M1'!$A:$A,$A8,'M1'!$B:$B,"ИТОГО ОТДЕЛ")/SUMIFS('M1'!$E:$E,'M1'!$A:$A,$A8,'M1'!$B:$B,"ИТОГО ОТДЕЛ"),"") -> 0.44715648 | C8: =IFERROR(SUMIFS('M2'!$F:$F,'M2'!$A:$A,$A8,'M2'!$B:$B,"ИТОГО ОТДЕЛ")/SUMIFS('M2'!$E:$E,'M2'!$A:$A,$A8,'M2'!$B:$B,"ИТОГО ОТДЕЛ"),"") -> 0.13463677 | D8: =SUMIFS('M1'!$E:$E,'M1'!$A:$A,$A8,'M1'!$B:$B,"ИТОГО ОТДЕЛ") -> 5986766.9 | E8: =SUMIFS('M2'!$E:$E,'M2'!$A:$A,$A8,'M2'!$B:$B,"ИТОГО ОТДЕЛ") -> 545022
A9: Февраль 2023 | B9: =IFERROR(SUMIFS('M1'!$F:$F,'M1'!$A:$A,$A9,'M1'!$B:$B,"ИТОГО ОТДЕЛ")/SUMIFS('M1'!$E:$E,'M1'!$A:$A,$A9,'M1'!$B:$B,"ИТОГО ОТДЕЛ"),"") -> 0.73789301 | C9: =IFERROR(SUMIFS('M2'!$F:$F,'M2'!$A:$A,$A9,'M2'!$B:$B,"ИТОГО ОТДЕЛ")/SUMIFS('M2'!$E:$E,'M2'!$A:$A,$A9,'M2'!$B:$B,"ИТОГО ОТДЕЛ"),"") -> 0.090870628 | D9: =SUMIFS('M1'!$E:$E,'M1'!$A:$A,$A9,'M1'!$B:$B,"ИТОГО ОТДЕЛ") -> 2549075.5 | E9: =SUMIFS('M2'!$E:$E,'M2'!$A:$A,$A9,'M2'!$B:$B,"ИТОГО ОТДЕЛ") -> 2890042.8
A10: Март 2023 | B10: =IFERROR(SUMIFS('M1'!$F:$F,'M1'!$A:$A,$A10,'M1'!$B:$B,"ИТОГО ОТДЕЛ")/SUMIFS('M1'!$E:$E,'M1'!$A:$A,$A10,'M1'!$B:$B,"ИТОГО ОТДЕЛ"),"") -> 0.66957166 | C10: =IFERROR(SUMIFS('M2'!$F:$F,'M2'!$A:$A,$A10,'M2'!$B:$B,"ИТОГО ОТДЕЛ")/SUMIFS('M2'!$E:$E,'M2'!$A:$A,$A10,'M2'!$B:$B,"ИТОГО ОТДЕЛ"),"") -> 0.16166211 | D10: =SUMIFS('M1'!$E:$E,'M1'!$A:$A,$A10,'M1'!$B:$B,"ИТОГО ОТДЕЛ") -> 1899332.8 | E10: =SUMIFS('M2'!$E:$E,'M2'!$A:$A,$A10,'M2'!$B:$B,"ИТОГО ОТДЕЛ") -> 760840.5
A11: Апрель 2023 | B11: =IFERROR(SUMIFS('M1'!$F:$F,'M1'!$A:$A,$A11,'M1'!$B:$B,"ИТОГО ОТДЕЛ")/SUMIFS('M1'!$E:$E,'M1'!$A:$A,$A11,'M1'!$B:$B,"ИТОГО ОТДЕЛ"),"") -> 0.50358131 | C11: =IFERROR(SUMIFS('M2'!$F:$F,'M2'!$A:$A,$A11,'M2'!$B:$B,"ИТОГО ОТДЕЛ")/SUMIFS('M2'!$E:$E,'M2'!$A:$A,$A11,'M2'!$B:$B,"ИТОГО ОТДЕЛ"),"") -> 0.092300095 | D11: =SUMIFS('M1'!$E:$E,'M1'!$A:$A,$A11,'M1'!$B:$B,"ИТОГО ОТДЕЛ") -> 2982484.3 | E11: =SUMIFS('M2'!$E:$E,'M2'!$A:$A,$A11,'M2'!$B:$B,"ИТОГО ОТДЕЛ") -> 627735
A12: Май 2023 | B12: =IFERROR(SUMIFS('M1'!$F:$F,'M1'!$A:$A,$A12,'M1'!$B:$B,"ИТОГО ОТДЕЛ")/SUMIFS('M1'!$E:$E,'M1'!$A:$A,$A12,'M1'!$B:$B,"ИТОГО ОТДЕЛ"),"") -> 0.58022711 | C12: =IFERROR(SUMIFS('M2'!$F:$F,'M2'!$A:$A,$A12,'M2'!$B:$B,"ИТОГО ОТДЕЛ")/SUMIFS('M2'!$E:$E,'M2'!$A:$A,$A12,'M2'!$B:$B,"ИТОГО ОТДЕЛ"),"") -> 0 | D12: =SUMIFS('M1'!$E:$E,'M1'!$A:$A,$A12,'M1'!$B:$B,"ИТОГО ОТДЕЛ") -> 3414631.5 | E12: =SUMIFS('M2'!$E:$E,'M2'!$A:$A,$A12,'M2'!$B:$B,"ИТОГО ОТДЕЛ") -> 1401445.9
A13: Июнь 2023 | B13: =IFERROR(SUMIFS('M1'!$F:$F,'M1'!$A:$A,$A13,'M1'!$B:$B,"ИТОГО ОТДЕЛ")/SUMIFS('M1'!$E:$E,'M1'!$A:$A,$A13,'M1'!$B:$B,"ИТОГО ОТДЕЛ"),"") -> 0.26130677 | C13: =IFERROR(SUMIFS('M2'!$F:$F,'M2'!$A:$A,$A13,'M2'!$B:$B,"ИТОГО ОТДЕЛ")/SUMIFS('M2'!$E:$E,'M2'!$A:$A,$A13,'M2'!$B:$B,"ИТОГО ОТДЕЛ"),"") -> 0.038059008 | D13: =SUMIFS('M1'!$E:$E,'M1'!$A:$A,$A13,'M1'!$B:$B,"ИТОГО ОТДЕЛ") -> 1274625.5 | E13: =SUMIFS('M2'!$E:$E,'M2'!$A:$A,$A13,'M2'!$B:$B,"ИТОГО ОТДЕЛ") -> 1015068.5
A14: Июль 2023 | B14: =IFERROR(SUMIFS('M1'!$F:$F,'M1'!$A:$A,$A14,'M1'!$B:$B,"ИТОГО ОТДЕЛ")/SUMIFS('M1'!$E:$E,'M1'!$A:$A,$A14,'M1'!$B:$B,"ИТОГО ОТДЕЛ"),"") -> 0.52948213 | C14: =IFERROR(SUMIFS('M2'!$F:$F,'M2'!$A:$A,$A14,'M2'!$B:$B,"ИТОГО ОТДЕЛ")/SUMIFS('M2'!$E:$E,'M2'!$A:$A,$A14,'M2'!$B:$B,"ИТОГО ОТДЕЛ"),"") -> 0.10612789 | D14: =SUMIFS('M1'!$E:$E,'M1'!$A:$A,$A14,'M1'!$B:$B,"ИТОГО ОТДЕЛ") -> 2625982.9 | E14: =SUMIFS('M2'!$E:$E,'M2'!$A:$A,$A14,'M2'!$B:$B,"ИТОГО ОТДЕЛ") -> 1020325.5
A15: Август 2023 | B15: =IFERROR(SUMIFS('M1'!$F:$F,'M1'!$A:$A,$A15,'M1'!$B:$B,"ИТОГО ОТДЕЛ")/SUMIFS('M1'!$E:$E,'M1'!$A:$A,$A15,'M1'!$B:$B,"ИТОГО ОТДЕЛ"),"") -> 0.48720696 | C15: =IFERROR(SUMIFS('M2'!$F:$F,'M2'!$A:$A,$A15,'M2'!$B:$B,"ИТОГО ОТДЕЛ")/SUMIFS('M2'!$E:$E,'M2'!$A:$A,$A15,'M2'!$B:$B,"ИТОГО ОТДЕЛ"),"") -> 0.036017215 | D15: =SUMIFS('M1'!$E:$E,'M1'!$A:$A,$A15,'M1'!$B:$B,"ИТОГО ОТДЕЛ") -> 1936915.8 | E15: =SUMIFS('M2'!$E:$E,'M2'!$A:$A,$A15,'M2'!$B:$B,"ИТОГО ОТДЕЛ") -> 1452499.9
A16: Сентябрь 2023 | B16: =IFERROR(SUMIFS('M1'!$F:$F,'M1'!$A:$A,$A16,'M1'!$B:$B,"ИТОГО ОТДЕЛ")/SUMIFS('M1'!$E:$E,'M1'!$A:$A,$A16,'M1'!$B:$B,"ИТОГО ОТДЕЛ"),"") -> 0.33513622 | C16: =IFERROR(SUMIFS('M2'!$F:$F,'M2'!$A:$A,$A16,'M2'!$B:$B,"ИТОГО ОТДЕЛ")/SUMIFS('M2'!$E:$E,'M2'!$A:$A,$A16,'M2'!$B:$B,"ИТОГО ОТДЕЛ"),"") -> 0 | D16: =SUMIFS('M1'!$E:$E,'M1'!$A:$A,$A16,'M1'!$B:$B,"ИТОГО ОТДЕЛ") -> 3241978.5 | E16: =SUMIFS('M2'!$E:$E,'M2'!$A:$A,$A16,'M2'!$B:$B,"ИТОГО ОТДЕЛ") -> 755739.63
A17: Октябрь 2023 | B17: =IFERROR(SUMIFS('M1'!$F:$F,'M1'!$A:$A,$A17,'M1'!$B:$B,"ИТОГО ОТДЕЛ")/SUMIFS('M1'!$E:$E,'M1'!$A:$A,$A17,'M1'!$B:$B,"ИТОГО ОТДЕЛ"),"") -> 0.81767756 | C17: =IFERROR(SUMIFS('M2'!$F:$F,'M2'!$A:$A,$A17,'M2'!$B:$B,"ИТОГО ОТДЕЛ")/SUMIFS('M2'!$E:$E,'M2'!$A:$A,$A17,'M2'!$B:$B,"ИТОГО ОТДЕЛ"),"") -> 0.11239702 | D17: =SUMIFS('M1'!$E:$E,'M1'!$A:$A,$A17,'M1'!$B:$B,"ИТОГО ОТДЕЛ") -> 3686850.8 | E17: =SUMIFS('M2'!$E:$E,'M2'!$A:$A,$A17,'M2'!$B:$B,"ИТОГО ОТДЕЛ") -> 2183145.1
A18: Ноябрь 2023 | B18: =IFERROR(SUMIFS('M1'!$F:$F,'M1'!$A:$A,$A18,'M1'!$B:$B,"ИТОГО ОТДЕЛ")/SUMIFS('M1'!$E:$E,'M1'!$A:$A,$A18,'M1'!$B:$B,"ИТОГО ОТДЕЛ"),"") -> 0.51788227 | C18: =IFERROR(SUMIFS('M2'!$F:$F,'M2'!$A:$A,$A18,'M2'!$B:$B,"ИТОГО ОТДЕЛ")/SUMIFS('M2'!$E:$E,'M2'!$A:$A,$A18,'M2'!$B:$B,"ИТОГО ОТДЕЛ"),"") -> 0.018931474 | D18: =SUMIFS('M1'!$E:$E,'M1'!$A:$A,$A18,'M1'!$B:$B,"ИТОГО ОТДЕЛ") -> 1567140 | E18: =SUMIFS('M2'!$E:$E,'M2'!$A:$A,$A18,'M2'!$B:$B,"ИТОГО ОТДЕЛ") -> 1130392.7
A19: Декабрь 2023 | B19: =IFERROR(SUMIFS('M1'!$F:$F,'M1'!$A:$A,$A19,'M1'!$B:$B,"ИТОГО ОТДЕЛ")/SUMIFS('M1'!$E:$E,'M1'!$A:$A,$A19,'M1'!$B:$B,"ИТОГО ОТДЕЛ"),"") -> 0.54459542 | C19: =IFERROR(SUMIFS('M2'!$F:$F,'M2'!$A:$A,$A19,'M2'!$B:$B,"ИТОГО ОТДЕЛ")/SUMIFS('M2'!$E:$E,'M2'!$A:$A,$A19,'M2'!$B:$B,"ИТОГО ОТДЕЛ"),"") -> 0.15549811 | D19: =SUMIFS('M1'!$E:$E,'M1'!$A:$A,$A19,'M1'!$B:$B,"ИТОГО ОТДЕЛ") -> 2434794.9 | E19: =SUMIFS('M2'!$E:$E,'M2'!$A:$A,$A19,'M2'!$B:$B,"ИТОГО ОТДЕЛ") -> 735957.5
A21: Годовой рейтинг менеджеров
A22: Менеджер | B22: M1 | C22: M2 | D22: M1 база, ₽ | E22: M2 база, ₽ | F22: Вернувшаяся выручка, ₽
A23: =A42 -> Федорова Марина Васильевна | B23: =G42 -> 0 | C23: =M42 -> 0 | D23: =D42 -> 0 | E23: =J42 -> 0 | F23: =N42 -> 0
A24: =A35 -> Иванова Мария Сергеевна | B24: =G35 -> 0.3511455 | C24: =M35 -> 0 | D24: =D35 -> 4727657.2 | E24: =J35 -> 2503864.8 | F24: =N35 -> 1660095.5
A25: =A36 -> Кузнецов Михаил Иванович | B25: =G36 -> 0.47844844 | C25: =M36 -> 0 | D25: =D36 -> 982724.44 | E25: =J36 -> 167675 | F25: =N36 -> 470182.98
A26: =A39 -> Попова Екатерина Николаевна | B26: =G39 -> 0.51229586 | C26: =M39 -> 0.13786979 | D26: =D39 -> 3680853.1 | E26: =J39 -> 1750920.3 | F26: =N39 -> 2127084.8
A27: =A34 -> Васильев Артем Александрович | B27: =G34 -> 0.53055963 | C27: =M34 -> 0.088952484 | D27: =D34 -> 11133085 | E27: =J34 -> 5423587.5 | F27: =N34 -> 6389207
A28: =A41 -> Соколова Анастасия Викторовна | B28: =G41 -> 0.58456167 | C28: =M41 -> 0.060343191 | D28: =D41 -> 6798714.6 | E28: =J41 -> 2812662 | F28: =N41 -> 4143993
A29: =A37 -> Михайлов Андрей Сергеевич | B29: =G37 -> 0.66494139 | C29: =M37 -> 0 | D29: =D37 -> 3361833.6 | E29: =J37 -> 1056004.7 | F29: =N37 -> 2235422.3
A30: =A40 -> Смирнова Ольга Владимировна | B30: =G40 -> 0.7017268 | C30: =M40 -> 0.25367118 | D30: =D40 -> 2817219.6 | E30: =J40 -> 803500.8 | F30: =N40 -> 2180743.5
A31: =A38 -> Петрова Анна Дмитриевна | B31: =G38 -> 1.1111818 | C31: =M38 -> 0 | D31: =D38 -> 98492 | E31: =J38 -> 0 | F31: =N38 -> 109442.52
A33: Менеджер | B33: M1 проектов в базе | C33: M1 продлено | D33: M1 сумма базы, ₽ | E33: M1 сумма пролонгаций, ₽ | F33: M1 конверсия | G33: M1 коэффициент | H33: M2 проектов в базе | I33: M2 продлено | J33: M2 сумма базы, ₽ | K33: M2 сумма пролонгаций, ₽ | L33: M2 конверсия | M33: M2 коэффициент | N33: Всего вернувшаяся выручка, ₽
A34: Васильев Артем Александрович | B34: =SUMIFS('M1'!$C:$C,'M1'!$B:$B,$A34) -> 107 | C34: =SUMIFS('M1'!$D:$D,'M1'!$B:$B,$A34) -> 42 | D34: =SUMIFS('M1'!$E:$E,'M1'!$B:$B,$A34) -> 11133085 | E34: =SUMIFS('M1'!$F:$F,'M1'!$B:$B,$A34) -> 5906765.4 | F34: =IFERROR(C34/B34,"") -> 0.39252336 | G34: =IFERROR(E34/D34,0) -> 0.53055963 | H34: =SUMIFS('M2'!$C:$C,'M2'!$B:$B,$A34) -> 67 | I34: =SUMIFS('M2'!$D:$D,'M2'!$B:$B,$A34) -> 7 | J34: =SUMIFS('M2'!$E:$E,'M2'!$B:$B,$A34) -> 5423587.5 | K34: =SUMIFS('M2'!$F:$F,'M2'!$B:$B,$A34) -> 482441.58 | L34: =IFERROR(I34/H34,"") -> 0.10447761 | M34: =IFERROR(K34/J34,0) -> 0.088952484 | N34: =E34+K34 -> 6389207 | X34: Август 2023 | Z34: Апрель 2023 | AB34: Декабрь 2023 | AD34: Июль 2023 | AF34: Июнь 2023 | AH34: Май 2023 | AJ34: Март 2023 | AL34: Ноябрь 2023 | AN34: Октябрь 2023 | AP34: Сентябрь 2023 | AR34: Февраль 2023 | AT34: Январь 2023 | AV34: Total Sum of Сумма базы, ₽ | AW34: Total Sum of Сумма пролонгаций, ₽
A35: Иванова Мария Сергеевна | B35: =SUMIFS('M1'!$C:$C,'M1'!$B:$B,$A35) -> 47 | C35: =SUMIFS('M1'!$D:$D,'M1'!$B:$B,$A35) -> 15 | D35: =SUMIFS('M1'!$E:$E,'M1'!$B:$B,$A35) -> 4727657.2 | E35: =SUMIFS('M1'!$F:$F,'M1'!$B:$B,$A35) -> 1660095.5 | F35: =IFERROR(C35/B35,"") -> 0.31914894 | G35: =IFERROR(E35/D35,0) -> 0.3511455 | H35: =SUMIFS('M2'!$C:$C,'M2'!$B:$B,$A35) -> 33 | I35: =SUMIFS('M2'!$D:$D,'M2'!$B:$B,$A35) -> 0 | J35: =SUMIFS('M2'!$E:$E,'M2'!$B:$B,$A35) -> 2503864.8 | K35: =SUMIFS('M2'!$F:$F,'M2'!$B:$B,$A35) -> 0 | L35: =IFERROR(I35/H35,"") -> 0 | M35: =IFERROR(K35/J35,0) -> 0 | N35: =E35+K35 -> 1660095.5 | X35: Sum of Сумма базы, ₽ | Y35: Sum of Сумма пролонгаций, ₽ | Z35: Sum of Сумма базы, ₽ | AA35: Sum of Сумма пролонгаций, ₽ | AB35: Sum of Сумма базы, ₽ | AC35: Sum of Сумма пролонгаций, ₽ | AD35: Sum of Сумма базы, ₽ | AE35: Sum of Сумма пролонгаций, ₽ | AF35: Sum of Сумма базы, ₽ | AG35: Sum of Сумма пролонгаций, ₽ | AH35: Sum of Сумма базы, ₽ | AI35: Sum of Сумма пролонгаций, ₽ | AJ35: Sum of Сумма базы, ₽ | AK35: Sum of Сумма пролонгаций, ₽ | AL35: Sum of Сумма базы, ₽ | AM35: Sum of Сумма пролонгаций, ₽ | AN35: Sum of Сумма базы, ₽ | AO35: Sum of Сумма пролонгаций, ₽ | AP35: Sum of Сумма базы, ₽ | AQ35: Sum of Сумма пролонгаций, ₽ | AR35: Sum of Сумма базы, ₽ | AS35: Sum of Сумма пролонгаций, ₽ | AT35: Sum of Сумма базы, ₽ | AU35: Sum of Сумма пролонгаций, ₽
A36: Кузнецов Михаил Иванович | B36: =SUMIFS('M1'!$C:$C,'M1'!$B:$B,$A36) -> 15 | C36: =SUMIFS('M1'!$D:$D,'M1'!$B:$B,$A36) -> 7 | D36: =SUMIFS('M1'!$E:$E,'M1'!$B:$B,$A36) -> 982724.44 | E36: =SUMIFS('M1'!$F:$F,'M1'!$B:$B,$A36) -> 470182.98 | F36: =IFERROR(C36/B36,"") -> 0.46666667 | G36: =IFERROR(E36/D36,0) -> 0.47844844 | H36: =SUMIFS('M2'!$C:$C,'M2'!$B:$B,$A36) -> 4 | I36: =SUMIFS('M2'!$D:$D,'M2'!$B:$B,$A36) -> 0 | J36: =SUMIFS('M2'!$E:$E,'M2'!$B:$B,$A36) -> 167675 | K36: =SUMIFS('M2'!$F:$F,'M2'!$B:$B,$A36) -> 0 | L36: =IFERROR(I36/H36,"") -> 0 | M36: =IFERROR(K36/J36,0) -> 0 | N36: =E36+K36 -> 470182.98 | W36: Федорова Марина Васильевна | X36: 0 | Y36: 0 | Z36: 0 | AA36: 0 | AB36: 0 | AC36: 0 | AD36: 0 | AE36: 0 | AF36: 0 | AG36: 0 | AH36: 0 | AI36: 0 | AJ36: 0 | AK36: 0 | AL36: 0 | AM36: 0 | AN36: 0 | AO36: 0 | AP36: 0 | AQ36: 0 | AR36: 0 | AS36: 0 | AT36: 0 | AU36: 0 | AV36: 0 | AW36: 0
A37: Михайлов Андрей Сергеевич | B37: =SUMIFS('M1'!$C:$C,'M1'!$B:$B,$A37) -> 26 | C37: =SUMIFS('M1'!$D:$D,'M1'!$B:$B,$A37) -> 14 | D37: =SUMIFS('M1'!$E:$E,'M1'!$B:$B,$A37) -> 3361833.6 | E37: =SUMIFS('M1'!$F:$F,'M1'!$B:$B,$A37) -> 2235422.3 | F37: =IFERROR(C37/B37,"") -> 0.53846154 | G37: =IFERROR(E37/D37,0) -> 0.66494139 | H37: =SUMIFS('M2'!$C:$C,'M2'!$B:$B,$A37) -> 13 | I37: =SUMIFS('M2'!$D:$D,'M2'!$B:$B,$A37) -> 0 | J37: =SUMIFS('M2'!$E:$E,'M2'!$B:$B,$A37) -> 1056004.7 | K37: =SUMIFS('M2'!$F:$F,'M2'!$B:$B,$A37) -> 0 | L37: =IFERROR(I37/H37,"") -> 0 | M37: =IFERROR(K37/J37,0) -> 0 | N37: =E37+K37 -> 2235422.3 | W37: Соколова Анастасия Викторовна | X37: 846377.13 | Y37: 252695 | Z37: 441283 | AA37: 424685 | AB37: 1282095 | AC37: 759775 | AD37: 950990 | AE37: 542575 | AF37: 374280 | AG37: 129740 | AH37: 406525 | AI37: 84690 | AJ37: 713273.5 | AK37: 272430 | AL37: 679492.22 | AM37: 69190 | AN37: 1243428.6 | AO37: 769355 | AP37: 623012.6 | AQ37: 142458.97 | AR37: 1031011.3 | AS37: 233500 | AT37: 1019608.3 | AU37: 462899 | AV37: 9611376.6 | AW37: 4143993
A38: Петрова Анна Дмитриевна | B38: =SUMIFS('M1'!$C:$C,'M1'!$B:$B,$A38) -> 1 | C38: =SUMIFS('M1'!$D:$D,'M1'!$B:$B,$A38) -> 1 | D38: =SUMIFS('M1'!$E:$E,'M1'!$B:$B,$A38) -> 98492 | E38: =SUMIFS('M1'!$F:$F,'M1'!$B:$B,$A38) -> 109442.52 | F38: =IFERROR(C38/B38,"") -> 1 | G38: =IFERROR(E38/D38,0) -> 1.1111818 | H38: =SUMIFS('M2'!$C:$C,'M2'!$B:$B,$A38) -> 0 | I38: =SUMIFS('M2'!$D:$D,'M2'!$B:$B,$A38) -> 0 | J38: =SUMIFS('M2'!$E:$E,'M2'!$B:$B,$A38) -> 0 | K38: =SUMIFS('M2'!$F:$F,'M2'!$B:$B,$A38) -> 0 | L38: =IFERROR(I38/H38,"") | M38: =IFERROR(K38/J38,0) -> 0 | N38: =E38+K38 -> 109442.52 | W38: Смирнова Ольга Владимировна | X38: 326025 | Y38: 161220 | Z38: 93075 | AA38: 89920 | AB38: 621566 | AC38: 226988.3 | AD38: 168079.35 | AE38: 69385 | AF38: 134394.35 | AG38: 51395 | AH38: 0 | AI38: 0 | AJ38: 48000 | AK38: 55225 | AL38: 449761.45 | AM38: 227030 | AN38: 996660.7 | AO38: 908328.75 | AP38: 546788.54 | AQ38: 279686.45 | AR38: 86295 | AS38: 0 | AT38: 150075 | AU38: 111565 | AV38: 3620720.4 | AW38: 2180743.5
A39: Попова Екатерина Николаевна | B39: =SUMIFS('M1'!$C:$C,'M1'!$B:$B,$A39) -> 61 | C39: =SUMIFS('M1'!$D:$D,'M1'!$B:$B,$A39) -> 25 | D39: =SUMIFS('M1'!$E:$E,'M1'!$B:$B,$A39) -> 3680853.1 | E39: =SUMIFS('M1'!$F:$F,'M1'!$B:$B,$A39) -> 1885685.8 | F39: =IFERROR(C39/B39,"") -> 0.40983607 | G39: =IFERROR(E39/D39,0) -> 0.51229586 | H39: =SUMIFS('M2'!$C:$C,'M2'!$B:$B,$A39) -> 34 | I39: =SUMIFS('M2'!$D:$D,'M2'!$B:$B,$A39) -> 4 | J39: =SUMIFS('M2'!$E:$E,'M2'!$B:$B,$A39) -> 1750920.3 | K39: =SUMIFS('M2'!$F:$F,'M2'!$B:$B,$A39) -> 241399 | L39: =IFERROR(I39/H39,"") -> 0.11764706 | M39: =IFERROR(K39/J39,0) -> 0.13786979 | N39: =E39+K39 -> 2127084.8 | W39: Попова Екатерина Николаевна | X39: 501775 | Y39: 108120 | Z39: 476770 | AA39: 128810 | AB39: 113060 | AC39: 67850 | AD39: 397570 | AE39: 69700 | AF39: 208770 | AG39: 0 | AH39: 726260 | AI39: 351500 | AJ39: 576742 | AK39: 262080 | AL39: 112728.26 | AM39: 21400 | AN39: 1049576.1 | AO39: 787804.8 | AP39: 612650 | AQ39: 223145 | AR39: 331002 | AS39: 0 | AT39: 324870 | AU39: 106675 | AV39: 5431773.3 | AW39: 2127084.8
A40: Смирнова Ольга Владимировна | B40: =SUMIFS('M1'!$C:$C,'M1'!$B:$B,$A40) -> 50 | C40: =SUMIFS('M1'!$D:$D,'M1'!$B:$B,$A40) -> 21 | D40: =SUMIFS('M1'!$E:$E,'M1'!$B:$B,$A40) -> 2817219.6 | E40: =SUMIFS('M1'!$F:$F,'M1'!$B:$B,$A40) -> 1976918.5 | F40: =IFERROR(C40/B40,"") -> 0.42 | G40: =IFERROR(E40/D40,0) -> 0.7017268 | H40: =SUMIFS('M2'!$C:$C,'M2'!$B:$B,$A40) -> 21 | I40: =SUMIFS('M2'!$D:$D,'M2'!$B:$B,$A40) -> 4 | J40: =SUMIFS('M2'!$E:$E,'M2'!$B:$B,$A40) -> 803500.8 | K40: =SUMIFS('M2'!$F:$F,'M2'!$B:$B,$A40) -> 203825 | L40: =IFERROR(I40/H40,"") -> 0.19047619 | M40: =IFERROR(K40/J40,0) -> 0.25367118 | N40: =E40+K40 -> 2180743.5 | W40: Петрова Анна Дмитриевна | X40: 0 | Y40: 0 | Z40: 0 | AA40: 0 | AB40: 98492 | AC40: 109442.52 | AD40: 0 | AE40: 0 | AF40: 0 | AG40: 0 | AH40: 0 | AI40: 0 | AJ40: 0 | AK40: 0 | AL40: 0 | AM40: 0 | AN40: 0 | AO40: 0 | AP40: 0 | AQ40: 0 | AR40: 0 | AS40: 0 | AT40: 0 | AU40: 0 | AV40: 98492 | AW40: 109442.52
A41: Соколова Анастасия Викторовна | B41: =SUMIFS('M1'!$C:$C,'M1'!$B:$B,$A41) -> 72 | C41: =SUMIFS('M1'!$D:$D,'M1'!$B:$B,$A41) -> 34 | D41: =SUMIFS('M1'!$E:$E,'M1'!$B:$B,$A41) -> 6798714.6 | E41: =SUMIFS('M1'!$F:$F,'M1'!$B:$B,$A41) -> 3974268 | F41: =IFERROR(C41/B41,"") -> 0.47222222 | G41: =IFERROR(E41/D41,0) -> 0.58456167 | H41: =SUMIFS('M2'!$C:$C,'M2'!$B:$B,$A41) -> 36 | I41: =SUMIFS('M2'!$D:$D,'M2'!$B:$B,$A41) -> 3 | J41: =SUMIFS('M2'!$E:$E,'M2'!$B:$B,$A41) -> 2812662 | K41: =SUMIFS('M2'!$F:$F,'M2'!$B:$B,$A41) -> 169725 | L41: =IFERROR(I41/H41,"") -> 0.083333333 | M41: =IFERROR(K41/J41,0) -> 0.060343191 | N41: =E41+K41 -> 4143993 | W41: Михайлов Андрей Сергеевич | X41: 0 | Y41: 0 | Z41: 77937.1 | AA41: 85640.35 | AB41: 50640 | AC41: 0 | AD41: 276105.18 | AE41: 94820 | AF41: 196925.18 | AG41: 0 | AH41: 410460 | AI41: 488289.75 | AJ41: 5306.6 | AK41: 12898.1 | AL41: 337060.75 | AM41: 0 | AN41: 999884.5 | AO41: 299100 | AP41: 333853.75 | AQ41: 0 | AR41: 1047560 | AS41: 813660 | AT41: 682105.21 | AU41: 441014.09 | AV41: 4417838.3 | AW41: 2235422.3
A42: Федорова Марина Васильевна | B42: =SUMIFS('M1'!$C:$C,'M1'!$B:$B,$A42) -> 0 | C42: =SUMIFS('M1'!$D:$D,'M1'!$B:$B,$A42) -> 0 | D42: =SUMIFS('M1'!$E:$E,'M1'!$B:$B,$A42) -> 0 | E42: =SUMIFS('M1'!$F:$F,'M1'!$B:$B,$A42) -> 0 | F42: =IFERROR(C42/B42,"") | G42: =IFERROR(E42/D42,0) -> 0 | H42: =SUMIFS('M2'!$C:$C,'M2'!$B:$B,$A42) -> 0 | I42: =SUMIFS('M2'!$D:$D,'M2'!$B:$B,$A42) -> 0 | J42: =SUMIFS('M2'!$E:$E,'M2'!$B:$B,$A42) -> 0 | K42: =SUMIFS('M2'!$F:$F,'M2'!$B:$B,$A42) -> 0 | L42: =IFERROR(I42/H42,"") | M42: =IFERROR(K42/J42,0) -> 0 | N42: =E42+K42 -> 0 | W42: Кузнецов Михаил Иванович | X42: 0 | Y42: 0 | Z42: 1425 | AA42: 0 | AB42: 654631.91 | AC42: 133822.34 | AD42: 0 | AE42: 0 | AF42: 0 | AG42: 0 | AH42: 1425 | AI42: 0 | AJ42: 0 | AK42: 0 | AL42: 330376.47 | AM42: 156480 | AN42: 43951.06 | AO42: 57510.64 | AP42: 0 | AQ42: 0 | AR42: 66255 | AS42: 56115 | AT42: 52335 | AU42: 66255 | AV42: 1150399.4 | AW42: 470182.98
A43: без А/М | B43: =SUMIFS('M1'!$C:$C,'M1'!$B:$B,$A43) -> 1 | C43: =SUMIFS('M1'!$D:$D,'M1'!$B:$B,$A43) -> 0 | D43: =SUMIFS('M1'!$E:$E,'M1'!$B:$B,$A43) -> 0 | E43: =SUMIFS('M1'!$F:$F,'M1'!$B:$B,$A43) -> 0 | F43: =IFERROR(C43/B43,"") -> 0 | G43: =IFERROR(E43/D43,0) -> 0 | H43: =SUMIFS('M2'!$C:$C,'M2'!$B:$B,$A43) -> 1 | I43: =SUMIFS('M2'!$D:$D,'M2'!$B:$B,$A43) -> 0 | J43: =SUMIFS('M2'!$E:$E,'M2'!$B:$B,$A43) -> 0 | K43: =SUMIFS('M2'!$F:$F,'M2'!$B:$B,$A43) -> 0 | L43: =IFERROR(I43/H43,"") -> 0 | M43: =IFERROR(K43/J43,0) -> 0 | N43: =E43+K43 -> 0 | W43: Иванова Мария Сергеевна | X43: 574220.95 | Y43: 164058.88 | Z43: 949173.75 | AA43: 228248 | AB43: 0 | AC43: 0 | AD43: 731122.25 | AE43: 200525 | AF43: 306830 | AG43: 0 | AH43: 616898 | AI43: 138158 | AJ43: 229633.75 | AK43: 102433.75 | AL43: 0 | AM43: 0 | AN43: 0 | AO43: 0 | AP43: 245372.5 | AQ43: 206440 | AR43: 1229435 | AS43: 0 | AT43: 2348835.7 | AU43: 620231.92 | AV43: 7231521.9 | AW43: 1660095.6
A44: ИТОГО ОТДЕЛ | B44: =SUMIFS('M1'!$C:$C,'M1'!$B:$B,$A44) -> 380 | C44: =SUMIFS('M1'!$D:$D,'M1'!$B:$B,$A44) -> 159 | D44: =SUMIFS('M1'!$E:$E,'M1'!$B:$B,$A44) -> 33600579 | E44: =SUMIFS('M1'!$F:$F,'M1'!$B:$B,$A44) -> 18218781 | F44: =IFERROR(C44/B44,"") -> 0.41842105 | G44: =IFERROR(E44/D44,"") -> 0.54221628 | H44: =SUMIFS('M2'!$C:$C,'M2'!$B:$B,$A44) -> 209 | I44: =SUMIFS('M2'!$D:$D,'M2'!$B:$B,$A44) -> 18 | J44: =SUMIFS('M2'!$E:$E,'M2'!$B:$B,$A44) -> 14518215 | K44: =SUMIFS('M2'!$F:$F,'M2'!$B:$B,$A44) -> 1097390.6 | L44: =IFERROR(I44/H44,"") -> 0.086124402 | M44: =IFERROR(K44/J44,"") -> 0.075587156 | N44: =E44+K44 -> 19316172 | W44: Васильев Артем Александрович | X44: 1141017.6 | Y44: 309900 | Z44: 1570555.4 | AA44: 602560 | AB44: 350267.5 | AC44: 142540 | AD44: 1122441.6 | AE44: 521691 | AF44: 1068494.5 | AG44: 190565.78 | AH44: 2654509.4 | AI44: 918624 | AJ44: 1087217.4 | AK44: 689671.63 | AL44: 788113.5 | AM44: 358894 | AN44: 1536495 | AO44: 437935 | AP44: 1636040.7 | AQ44: 234774 | AR44: 1647560 | AS44: 1040290 | AT44: 1953959.7 | AU44: 941761.6 | AV44: 16556672 | AW44: 6389207
...

Sheet M1
A1: Месяц отчета | B1: Менеджер | C1: Проектов в базе | D1: Продлено проектов | E1: Сумма базы, ₽ | F1: Сумма пролонгаций, ₽ | G1: Конверсия по проектам | H1: Коэффициент пролонгации
A2: Январь 2023 | B2: Васильев Артем Александрович | C2: 22 | D2: 6 | E2: 1693097.7 | F2: 941761.6 | G2: =IFERROR(D2/C2,"") -> 0.27272727 | H2: =IFERROR(F2/E2,"") -> 0.55623583
A3: Январь 2023 | B3: Иванова Мария Сергеевна | C3: 16 | D3: 4 | E3: 2296595.7 | F3: 620231.92 | G3: =IFERROR(D3/C3,"") -> 0.25 | H3: =IFERROR(F3/E3,"") -> 0.27006578
A4: Январь 2023 | B4: Кузнецов Михаил Иванович | C4: 1 | D4: 1 | E4: 52335 | F4: 66255 | G4: =IFERROR(D4/C4,"") -> 1 | H4: =IFERROR(F4/E4,"") -> 1.2659788
A5: Январь 2023 | B5: Михайлов Андрей Сергеевич | C5: 10 | D5: 4 | E5: 641080.21 | F5: 441014.09 | G5: =IFERROR(D5/C5,"") -> 0.4 | H5: =IFERROR(F5/E5,"") -> 0.68792342
A6: Январь 2023 | B6: Петрова Анна Дмитриевна | C6: 0 | D6: 0 | E6: 0 | F6: 0 | G6: =IFERROR(D6/C6,"") | H6: =IFERROR(F6/E6,"")
A7: Январь 2023 | B7: Попова Екатерина Николаевна | C7: 6 | D7: 2 | E7: 242070 | F7: 106675 | G7: =IFERROR(D7/C7,"") -> 0.33333333 | H7: =IFERROR(F7/E7,"") -> 0.44067832
A8: Январь 2023 | B8: Смирнова Ольга Владимировна | C8: 3 | D8: 2 | E8: 150075 | F8: 111565 | G8: =IFERROR(D8/C8,"") -> 0.66666667 | H8: =IFERROR(F8/E8,"") -> 0.74339497
A9: Январь 2023 | B9: Соколова Анастасия Викторовна | C9: 9 | D9: 4 | E9: 911513.26 | F9: 389519 | G9: =IFERROR(D9/C9,"") -> 0.44444444 | H9: =IFERROR(F9/E9,"") -> 0.42733224
A10: Январь 2023 | B10: Федорова Марина Васильевна | C10: 0 | D10: 0 | E10: 0 | F10: 0 | G10: =IFERROR(D10/C10,"") | H10: =IFERROR(F10/E10,"")
A11: Январь 2023 | B11: без А/М | C11: 0 | D11: 0 | E11: 0 | F11: 0 | G11: =IFERROR(D11/C11,"") | H11: =IFERROR(F11/E11,"")
A12: Январь 2023 | B12: ИТОГО ОТДЕЛ | C12: 67 | D12: 23 | E12: 5986766.9 | F12: 2677021.6 | G12: =IFERROR(D12/C12,"") -> 0.34328358 | H12: =IFERROR(F12/E12,"") -> 0.44715648
A13: Февраль 2023 | B13: Васильев Артем Александрович | C13: 5 | D13: 2 | E13: 756225 | F13: 874015 | G13: =IFERROR(D13/C13,"") -> 0.4 | H13: =IFERROR(F13/E13,"") -> 1.1557605
... A133: Декабрь 2023 | B133: ИТОГО ОТДЕЛ | C133: 40 | D133: 14 | E133: 2434794.9 | F133: 1325978.2 | G133: =IFERROR(D133/C133,"") -> 0.35 | H133: =IFERROR(F133/E133,"") -> 0.54459542

Sheet M2
A1: Месяц отчета | B1: Менеджер | C1: Проектов в базе | D1: Продлено проектов | E1: Сумма базы, ₽ | F1: Сумма пролонгаций, ₽ | G1: Конверсия по проектам | H1: Коэффициент пролонгации
A2: Январь 2023 | B2: Васильев Артем Александрович | C2: 8 | D2: 0 | E2: 260862 | F2: 0 | G2: =IFERROR(D2/C2,"") -> 0 | H2: =IFERROR(F2/E2,"") -> 0
A3: Январь 2023 | B3: Иванова Мария Сергеевна | C3: 1 | D3: 0 | E3: 52240 | F3: 0 | G3: =IFERROR(D3/C3,"") -> 0 | H3: =IFERROR(F3/E3,"") -> 0
A4: Январь 2023 | B4: Кузнецов Михаил Иванович | C4: 0 | D4: 0 | E4: 0 | F4: 0 | G4: =IFERROR(D4/C4,"") | H4: =IFERROR(F4/E4,"")
A5: Январь 2023 | B5: Михайлов Андрей Сергеевич | C5: 2 | D5: 0 | E5: 41025 | F5: 0 | G5: =IFERROR(D5/C5,"") -> 0 | H5: =IFERROR(F5/E5,"") -> 0
A6: Январь 2023 | B6: Петрова Анна Дмитриевна | C6: 0 | D6: 0 | E6: 0 | F6: 0 | G6: =IFERROR(D6/C6,"") | H6: =IFERROR(F6/E6,"")
A7: Январь 2023 | B7: Попова Екатерина Николаевна | C7: 1 | D7: 0 | E7: 82800 | F7: 0 | G7: =IFERROR(D7/C7,"") -> 0 | H7: =IFERROR(F7/E7,"") -> 0
A8: Январь 2023 | B8: Смирнова Ольга Владимировна | C8: 0 | D8: 0 | E8: 0 | F8: 0 | G8: =IFERROR(D8/C8,"") | H8: =IFERROR(F8/E8,"")
A9: Январь 2023 | B9: Соколова Анастасия Викторовна | C9: 2 | D9: 1 | E9: 108095 | F9: 73380 | G9: =IFERROR(D9/C9,"") -> 0.5 | H9: =IFERROR(F9/E9,"") -> 0.67884731
A10: Январь 2023 | B10: Федорова Марина Васильевна | C10: 0 | D10: 0 | E10: 0 | F10: 0 | G10: =IFERROR(D10/C10,"") | H10: =IFERROR(F10/E10,"")
A11: Январь 2023 | B11: без А/М | C11: 0 | D11: 0 | E11: 0 | F11: 0 | G11: =IFERROR(D11/C11,"") | H11: =IFERROR(F11/E11,"")
A12: Январь 2023 | B12: ИТОГО ОТДЕЛ | C12: 14 | D12: 1 | E12: 545022 | F12: 73380 | G12: =IFERROR(D12/C12,"") -> 0.071428571 | H12: =IFERROR(F12/E12,"") -> 0.13463677
A13: Февраль 2023 | B13: Васильев Артем Александрович | C13: 16 | D13: 2 | E13: 891335 | F13: 166275 | G13: =IFERROR(D13/C13,"") -> 0.125 | H13: =IFERROR(F13/E13,"") -> 0.18654602
... A133: Декабрь 2023 | B133: ИТОГО ОТДЕЛ | C133: 14 | D133: 2 | E133: 735957.5 | F133: 114440 | G133: =IFERROR(D133/C133,"") -> 0.14285714 | H133: =IFERROR(F133/E133,"") -> 0.15549811

Sheet Main
A1: Месяц отчета | B1: Коэффициент | C1: Менеджер | D1: Проектов в базе | E1: Продлено проектов | F1: Сумма базы, ₽ | G1: Сумма пролонгаций, ₽ | H1: Конверсия по проектам | I1: Коэффициент пролонгации
A2: Январь 2023 | B2: M1 | C2: Васильев Артем Александрович | D2: 22 | E2: 6 | F2: 1693097.7 | G2: 941761.6 | H2: =IFERROR(E2/D2,"") -> 0.27272727 | I2: =IFERROR(G2/F2,"") -> 0.55623583
A3: Январь 2023 | B3: M1 | C3: Иванова Мария Сергеевна | D3: 16 | E3: 4 | F3: 2296595.7 | G3: 620231.92 | H3: =IFERROR(E3/D3,"") -> 0.25 | I3: =IFERROR(G3/F3,"") -> 0.27006578
A4: Январь 2023 | B4: M1 | C4: Кузнецов Михаил Иванович | D4: 1 | E4: 1 | F4: 52335 | G4: 66255 | H4: =IFERROR(E4/D4,"") -> 1 | I4: =IFERROR(G4/F4,"") -> 1.2659788
A5: Январь 2023 | B5: M1 | C5: Михайлов Андрей Сергеевич | D5: 10 | E5: 4 | F5: 641080.21 | G5: 441014.09 | H5: =IFERROR(E5/D5,"") -> 0.4 | I5: =IFERROR(G5/F5,"") -> 0.68792342
A6: Январь 2023 | B6: M1 | C6: Петрова Анна Дмитриевна | D6: 0 | E6: 0 | F6: 0 | G6: 0 | H6: =IFERROR(E6/D6,"") | I6: =IFERROR(G6/F6,"")
A7: Январь 2023 | B7: M1 | C7: Попова Екатерина Николаевна | D7: 6 | E7: 2 | F7: 242070 | G7: 106675 | H7: =IFERROR(E7/D7,"") -> 0.33333333 | I7: =IFERROR(G7/F7,"") -> 0.44067832
A8: Январь 2023 | B8: M1 | C8: Смирнова Ольга Владимировна | D8: 3 | E8: 2 | F8: 150075 | G8: 111565 | H8: =IFERROR(E8/D8,"") -> 0.66666667 | I8: =IFERROR(G8/F8,"") -> 0.74339497
A9: Январь 2023 | B9: M1 | C9: Соколова Анастасия Викторовна | D9: 9 | E9: 4 | F9: 911513.26 | G9: 389519 | H9: =IFERROR(E9/D9,"") -> 0.44444444 | I9: =IFERROR(G9/F9,"") -> 0.42733224
A10: Январь 2023 | B10: M1 | C10: Федорова Марина Васильевна | D10: 0 | E10: 0 | F10: 0 | G10: 0 | H10: =IFERROR(E10/D10,"") | I10: =IFERROR(G10/F10,"")
A11: Январь 2023 | B11: M1 | C11: без А/М | D11: 0 | E11: 0 | F11: 0 | G11: 0 | H11: =IFERROR(E11/D11,"") | I11: =IFERROR(G11/F11,"")
A12: Февраль 2023 | B12: M1 | C12: Васильев Артем Александрович | D12: 5 | E12: 2 | F12: 756225 | G12: 874015 | H12: =IFERROR(E12/D12,"") -> 0.4 | I12: =IFERROR(G12/F12,"") -> 1.1557605
A13: Февраль 2023 | B13: M1 | C13: Иванова Мария Сергеевна | D13: 0 | E13: 0 | F13: 0 | G13: 0 | H13: =IFERROR(E13/D13,"") | I13: =IFERROR(G13/F13,"")
... A241: Декабрь 2023 | B241: M2 | C241: без А/М | D241: 0 | E241: 0 | F241: 0 | G241: 0 | H241: =IFERROR(E241/D241,"") | I241: =IFERROR(G241/F241,"")
